> Running 'python telegram_bot.py'
Traceback (most recent call last):
  File "/opt/render/project/src/.venv/lib/python3.11/site-packages/telegram/ext/_application.py", line 881, in __run
    raise exc
  File "/opt/render/project/src/.venv/lib/python3.11/site-packages/telegram/ext/_application.py", line 873, in __run
    loop.run_until_complete(updater_coroutine)  # one of updater.start_webhook/polling
    ^^^^^^^^^^^^^^^^^^^^^^^^^^^^^^^^^^^^^^^^^^
  File "/opt/render/project/src/.venv/lib/python3.11/site-packages/nest_asyncio.py", line 90, in run_until_complete
    return f.result()
           ^^^^^^^^^^
  File "/usr/local/lib/python3.11/asyncio/futures.py", line 203, in result
    raise self._exception.with_traceback(self._exception_tb)
  File "/usr/local/lib/python3.11/asyncio/tasks.py", line 277, in __step
    result = coro.send(None)
             ^^^^^^^^^^^^^^^
  File "/opt/render/project/src/.venv/lib/python3.11/site-packages/telegram/ext/_updater.py", line 458, in start_webhook
    raise RuntimeError(
RuntimeError: To use `start_webhook`, PTB must be installed via `pip install python-telegram-bot[webhooks]`.
During handling of the above exception, another exception occurred:
Traceback (most recent call last):
  File "/opt/render/project/src/telegram_bot.py", line 310, in <module>
    asyncio.run(main())
  File "/opt/render/project/src/.venv/lib/python3.11/site-packages/nest_asyncio.py", line 35, in run
    return loop.run_until_complete(task)
           ^^^^^^^^^^^^^^^^^^^^^^^^^^^^^
  File "/opt/render/project/src/.venv/lib/python3.11/site-packages/nest_asyncio.py", line 90, in run_until_complete
    return f.result()
           ^^^^^^^^^^
  File "/usr/local/lib/python3.11/asyncio/futures.py", line 203, in result
    raise self._exception.with_traceback(self._exception_tb)
  File "/usr/local/lib/python3.11/asyncio/tasks.py", line 277, in __step
    result = coro.send(None)
             ^^^^^^^^^^^^^^^
  File "/opt/render/project/src/telegram_bot.py", line 302, in main
    await application.run_webhook(
          ^^^^^^^^^^^^^^^^^^^^^^^^
  File "/opt/render/project/src/.venv/lib/python3.11/site-packages/telegram/ext/_application.py", line 820, in run_webhook
    return self.__run(
           ^^^^^^^^^^^
  File "/opt/render/project/src/.venv/lib/python3.11/site-packages/telegram/ext/_application.py", line 895, in __run
    loop.close()
  File "/usr/local/lib/python3.11/asyncio/unix_events.py", line 68, in close
    super().close()
  File "/usr/local/lib/python3.11/asyncio/selector_events.py", line 88, in close
    raise RuntimeError("Cannot close a running event loop")
RuntimeError: Cannot close a running event loop
==> Exited with status 1
==> Common ways to troubleshoot your deploy: https://render.com/docs/troubleshooting-deploys
==> Running 'python telegram_bot.py'
Traceback (most recent call last):
  File "/opt/render/project/src/.venv/lib/python3.11/site-packages/telegram/ext/_application.py", line 881, in __run
    raise exc
  File "/opt/render/project/src/.venv/lib/python3.11/site-packages/telegram/ext/_application.py", line 873, in __run
    loop.run_until_complete(updater_coroutine)  # one of updater.start_webhook/polling
    ^^^^^^^^^^^^^^^^^^^^^^^^^^^^^^^^^^^^^^^^^^
  File "/opt/render/project/src/.venv/lib/python3.11/site-packages/nest_asyncio.py", line 90, in run_until_complete
    return f.result()
           ^^^^^^^^^^
  File "/usr/local/lib/python3.11/asyncio/futures.py", line 203, in result
    raise self._exception.with_traceback(self._exception_tb)
  File "/usr/local/lib/python3.11/asyncio/tasks.py", line 277, in __step
    result = coro.send(None)
             ^^^^^^^^^^^^^^^
  File "/opt/render/project/src/.venv/lib/python3.11/site-packages/telegram/ext/_updater.py", line 458, in start_webhook
    raise RuntimeError(
RuntimeError: To use `start_webhook`, PTB must be installed via `pip install python-telegram-bot[webhooks]`.
